Workbook

Sheet Carga cognitiva
A1: Joselin
A2: Variable | B2: (a) Peso | C2: (b) Puntuacion | D2: (c) Puntuacion Convertida (b*5) | E2: (d) Puntuacion Ponderada (c*a)
A3: Exigencia mental | B3: 4 | C3: 10 | D3: =PRODUCT(C3,5) -> 50 | E3: =PRODUCT(B3,D3) -> 200
A4: Exigencia fisica | B4: 0 | C4: 1 | D4: =PRODUCT(C4,5) -> 5 | E4: =PRODUCT(B4,D4) -> 0
A5: Exigencia Temporal | B5: 2 | C5: 15 | D5: =PRODUCT(C5,5) -> 75 | E5: =PRODUCT(B5,D5) -> 150
A6: Rendimiento | B6: 3 | C6: 15 | D6: =PRODUCT(C6,5) -> 75 | E6: =PRODUCT(B6,D6) -> 225
A7: Esfuerzo | B7: 4 | C7: 5 | D7: =PRODUCT(C7,5) -> 25 | E7: =PRODUCT(B7,D7) -> 100
A8: Frustacion | B8: 2 | C8: =D8/5 -> 4 | D8: 20 | E8: =PRODUCT(B8,D8) -> 40
A9: Total | B9: =SUM(B3,B4,B5,B6,B7,B8) -> 15 | E9: =SUM(E3:E8) -> 715 | F9: Porcentaje: | G9: =E9/B9 -> 47.666667
A11: Daniel
A13: Variable | B13: (a) Peso | C13: (b) Puntuacion | D13: (c) Puntuacion Convertida (b*5) | E13: (d) Puntuacion Ponderada (c*a)
A14: Exigencia mental | B14: 5 | C14: 16 | D14: =PRODUCT(C14,5) -> 80 | E14: =PRODUCT(B14,D14) -> 400
A15: Exigencia fisica | B15: 0 | C15: 2 | D15: =PRODUCT(C15,5) -> 10 | E15: =PRODUCT(B15,D15) -> 0
A16: Exigencia Temporal | B16: 1 | C16: 5 | D16: =PRODUCT(C16,5) -> 25 | E16: =PRODUCT(B16,D16) -> 25
A17: Rendimiento | B17: 4 | C17: 14 | D17: =PRODUCT(C17,5) -> 70 | E17: =PRODUCT(B17,D17) -> 280
A18: Esfuerzo | B18: 3 | C18: 13 | D18: =PRODUCT(C18,5) -> 65 | E18: =PRODUCT(B18,D18) -> 195
A19: Frustacion | B19: 2 | C19: =D19/5 -> 6 | D19: 30 | E19: =PRODUCT(B19,D19) -> 60
A20: Total | B20: =SUM(B14,B15,B16,B17,B18,B19) -> 15 | E20: =SUM(E14:E19) -> 960 | F20: Porcentaje: | G20: =E20/B20 -> 64
A22: Edwin
A24: Variable | B24: (a) Peso | C24: (b) Puntuacion | D24: (c) Puntuacion Convertida (b*5) | E24: (d) Puntuacion Ponderada (c*a)
A25: Exigencia mental | B25: 3 | C25: 12 | D25: =PRODUCT(C25,5) -> 60 | E25: =PRODUCT(B25,D25) -> 180
A26: Exigencia fisica | B26: 0 | C26: 2 | D26: =PRODUCT(C26,5) -> 10 | E26: =PRODUCT(B26,D26) -> 0
A27: Exigencia Temporal | B27: 4 | C27: 8 | D27: =PRODUCT(C27,5) -> 40 | E27: =PRODUCT(B27,D27) -> 160
A28: Rendimiento | B28: 2 | C28: 10 | D28: =PRODUCT(C28,5) -> 50 | E28: =PRODUCT(B28,D28) -> 100
A29: Esfuerzo | B29: 1 | C29: 3 | D29: =PRODUCT(C29,5) -> 15 | E29: =PRODUCT(B29,D29) -> 15
A30: Frustacion | B30: 5 | C30: =D30/5 -> 16 | D30: 80 | E30: =PRODUCT(B30,D30) -> 400
A31: Total | B31: =SUM(B25,B26,B27,B28,B29,B30) -> 15 | E31: =SUM(E25:E30) -> 855 | F31: Porcentaje: | G31: =E31/B31 -> 57
A33: Jeronimo
A35: Variable | B35: (a) Peso | C35: (b) Puntuacion | D35: (c) Puntuacion Convertida (b*5) | E35: (d) Puntuacion Ponderada (c*a)
A36: Exigencia mental | B36: 2 | C36: 1 | D36: =PRODUCT(C36,5) -> 5 | E36: =PRODUCT(B36,D36) -> 10
A37: Exigencia fisica | B37: 1 | C37: 1 | D37: =PRODUCT(C37,5) -> 5 | E37: =PRODUCT(B37,D37) -> 5
A38: Exigencia Temporal | B38: 4 | C38: 10 | D38: =PRODUCT(C38,5) -> 50 | E38: =PRODUCT(B38,D38) -> 200
A39: Rendimiento | B39: 5 | C39: 15 | D39: =PRODUCT(C39,5) -> 75 | E39: =PRODUCT(B39,D39) -> 375
A40: Esfuerzo | B40: 3 | C40: 7 | D40: =PRODUCT(C40,5) -> 35 | E40: =PRODUCT(B40,D40) -> 105
A41: Frustacion | B41: 0 | C41: =D41/5 -> 5 | D41: 25 | E41: =PRODUCT(B41,D41) -> 0
A42: Total | B42: =SUM(B36,B37,B38,B39,B40,B41) -> 15 | E42: =SUM(E36:E41) -> 695 | F42: Porcentaje: | G42: =E42/B42 -> 46.333333
A44: Rafa
A46: Variable | B46: (a) Peso | C46: (b) Puntuacion | D46: (c) Puntuacion Convertida (b*5) | E46: (d) Puntuacion Ponderada (c*a)
A47: Exigencia mental | B47: 5 | C47: 9 | D47: =PRODUCT(C47,5) -> 45 | E47: =PRODUCT(B47,D47) -> 225
A48: Exigencia fisica | B48: 1 | C48: 3 | D48: =PRODUCT(C48,5) -> 15 | E48: =PRODUCT(B48,D48) -> 15
...

Sheet CanQuest (Hápticos)
A1: Variable | B1: (a) Peso | C1: (b) Puntuacion | D1: (c) Puntuacion Convertida (b*5) | E1: (d) Puntuacion Ponderada (c*a)
A2: Exigencia mental | B2: 2 | C2: 5 | D2: =PRODUCT(C2,5) -> 25 | E2: =PRODUCT(B2,D2) -> 50
A3: Exigencia fisica | B3: 4 | C3: 10 | D3: =PRODUCT(C3,5) -> 50 | E3: =PRODUCT(B3,D3) -> 200
A4: Exigencia Temporal | B4: 0 | C4: 2 | D4: =PRODUCT(C4,5) -> 10 | E4: =PRODUCT(B4,D4) -> 0
A5: Rendimiento | B5: 5 | C5: 15 | D5: =PRODUCT(C5,5) -> 75 | E5: =PRODUCT(B5,D5) -> 375
A6: Esfuerzo | B6: 3 | C6: 10 | D6: =PRODUCT(C6,5) -> 50 | E6: =PRODUCT(B6,D6) -> 150
A7: Frustacion | B7: 1 | C7: =D7/5 -> 2 | D7: 10 | E7: =PRODUCT(B7,D7) -> 10
A8: Total | B8: =SUM(B2,B3,B4,B5,B6,B7) -> 15 | E8: =SUM(E2:E7) -> 785 | F8: Porcentaje: | G8: =E8/B8 -> 52.333333
A11: Variable | B11: (a) Peso | C11: (b) Puntuacion | D11: (c) Puntuacion Convertida (b*5) | E11: (d) Puntuacion Ponderada (c*a)
A12: Exigencia mental | B12: 1 | C12: 4 | D12: =PRODUCT(C12,5) -> 20 | E12: =PRODUCT(B12,D12) -> 20
A13: Exigencia fisica | B13: 0 | C13: 5 | D13: =PRODUCT(C13,5) -> 25 | E13: =PRODUCT(B13,D13) -> 0
A14: Exigencia Temporal | B14: 4 | C14: 10 | D14: =PRODUCT(C14,5) -> 50 | E14: =PRODUCT(B14,D14) -> 200
A15: Rendimiento | B15: 5 | C15: 14 | D15: =PRODUCT(C15,5) -> 70 | E15: =PRODUCT(B15,D15) -> 350
A16: Esfuerzo | B16: 2 | C16: 6 | D16: =PRODUCT(C16,5) -> 30 | E16: =PRODUCT(B16,D16) -> 60
A17: Frustacion | B17: 3 | C17: =D17/5 -> 3 | D17: 15 | E17: =PRODUCT(B17,D17) -> 45
A18: Total | B18: =SUM(B12,B13,B14,B15,B16,B17) -> 15 | E18: =SUM(E12:E17) -> 675 | F18: Porcentaje: | G18: =E18/B18 -> 45
A21: Variable | B21: (a) Peso | C21: (b) Puntuacion | D21: (c) Puntuacion Convertida (b*5) | E21: (d) Puntuacion Ponderada (c*a)
A22: Exigencia mental | B22: 1 | C22: 8 | D22: =PRODUCT(C22,5) -> 40 | E22: =PRODUCT(B22,D22) -> 40
A23: Exigencia fisica | B23: 2 | C23: 8 | D23: =PRODUCT(C23,5) -> 40 | E23: =PRODUCT(B23,D23) -> 80
A24: Exigencia Temporal | B24: 4 | C24: 13 | D24: =PRODUCT(C24,5) -> 65 | E24: =PRODUCT(B24,D24) -> 260
A25: Rendimiento | B25: 5 | C25: 15 | D25: =PRODUCT(C25,5) -> 75 | E25: =PRODUCT(B25,D25) -> 375
A26: Esfuerzo | B26: 3 | C26: 4 | D26: =PRODUCT(C26,5) -> 20 | E26: =PRODUCT(B26,D26) -> 60
A27: Frustacion | B27: 0 | C27: =D27/5 -> 5 | D27: 25 | E27: =PRODUCT(B27,D27) -> 0
A28: Total | B28: =SUM(B22,B23,B24,B25,B26,B27) -> 15 | E28: =SUM(E22:E27) -> 815 | F28: Porcentaje: | G28: =E28/B28 -> 54.333333
A30: Jeronimo
A32: Variable | B32: (a) Peso | C32: (b) Puntuacion | D32: (c) Puntuacion Convertida (b*5) | E32: (d) Puntuacion Ponderada (c*a)
A33: Exigencia mental | B33: 2 | C33: 1 | D33: =PRODUCT(C33,5) -> 5 | E33: =PRODUCT(B33,D33) -> 10
A34: Exigencia fisica | B34: 1 | C34: 1 | D34: =PRODUCT(C34,5) -> 5 | E34: =PRODUCT(B34,D34) -> 5
A35: Exigencia Temporal | B35: 4 | C35: 10 | D35: =PRODUCT(C35,5) -> 50 | E35: =PRODUCT(B35,D35) -> 200
A36: Rendimiento | B36: 5 | C36: 15 | D36: =PRODUCT(C36,5) -> 75 | E36: =PRODUCT(B36,D36) -> 375
A37: Esfuerzo | B37: 3 | C37: 7 | D37: =PRODUCT(C37,5) -> 35 | E37: =PRODUCT(B37,D37) -> 105
A38: Frustacion | B38: 0 | C38: =D38/5 -> 5 | D38: 25 | E38: =PRODUCT(B38,D38) -> 0
A39: Total | B39: =SUM(B33,B34,B35,B36,B37,B38) -> 15 | E39: =SUM(E33:E38) -> 695 | F39: Porcentaje: | G39: =E39/B39 -> 46.333333
A41: Rafa
A43: Variable | B43: (a) Peso | C43: (b) Puntuacion | D43: (c) Puntuacion Convertida (b*5) | E43: (d) Puntuacion Ponderada (c*a)
A44: Exigencia mental | B44: 2 | C44: 3 | D44: =PRODUCT(C44,5) -> 15 | E44: =PRODUCT(B44,D44) -> 30
A45: Exigencia fisica | B45: 5 | C45: 8 | D45: =PRODUCT(C45,5) -> 40 | E45: =PRODUCT(B45,D45) -> 200
A46: Exigencia Temporal | B46: 0 | C46: 10 | D46: =PRODUCT(C46,5) -> 50 | E46: =PRODUCT(B46,D46) -> 0
A47: Rendimiento | B47: 3 | C47: 20 | D47: =PRODUCT(C47,5) -> 100 | E47: =PRODUCT(B47,D47) -> 300
A48: Esfuerzo | B48: 4 | C48: 9 | D48: =PRODUCT(C48,5) -> 45 | E48: =PRODUCT(B48,D48) -> 180
...

Sheet CanQuest (Control)
A1: Joselin
A2: Variable | B2: (a) Peso | C2: (b) Puntuacion | D2: (c) Puntuacion Convertida (b*5) | E2: (d) Puntuacion Ponderada (c*a)
A3: Exigencia mental | B3: 3 | C3: 10 | D3: =PRODUCT(C3,5) -> 50 | E3: =PRODUCT(B3,D3) -> 150
A4: Exigencia fisica | B4: 1 | C4: 5 | D4: =PRODUCT(C4,5) -> 25 | E4: =PRODUCT(B4,D4) -> 25
A5: Exigencia Temporal | B5: 0 | C5: 12 | D5: =PRODUCT(C5,5) -> 60 | E5: =PRODUCT(B5,D5) -> 0
A6: Rendimiento | B6: 5 | C6: 5 | D6: =PRODUCT(C6,5) -> 25 | E6: =PRODUCT(B6,D6) -> 125
A7: Esfuerzo | B7: 3 | C7: 8 | D7: =PRODUCT(C7,5) -> 40 | E7: =PRODUCT(B7,D7) -> 120
A8: Frustacion | B8: 3 | C8: =D8/5 -> 10 | D8: 50 | E8: =PRODUCT(B8,D8) -> 150
A9: Total | B9: =SUM(B3,B4,B5,B6,B7,B8) -> 15 | E9: =SUM(E3:E8) -> 570 | F9: Porcentaje: | G9: =E9/B9 -> 38
A11: Daniel
A13: Variable | B13: (a) Peso | C13: (b) Puntuacion | D13: (c) Puntuacion Convertida (b*5) | E13: (d) Puntuacion Ponderada (c*a)
A14: Exigencia mental | B14: 5 | C14: 13 | D14: =PRODUCT(C14,5) -> 65 | E14: =PRODUCT(B14,D14) -> 325
A15: Exigencia fisica | B15: 0 | C15: 1 | D15: =PRODUCT(C15,5) -> 5 | E15: =PRODUCT(B15,D15) -> 0
A16: Exigencia Temporal | B16: 4 | C16: 6 | D16: =PRODUCT(C16,5) -> 30 | E16: =PRODUCT(B16,D16) -> 120
A17: Rendimiento | B17: 3 | C17: 13 | D17: =PRODUCT(C17,5) -> 65 | E17: =PRODUCT(B17,D17) -> 195
A18: Esfuerzo | B18: 2 | C18: 4 | D18: =PRODUCT(C18,5) -> 20 | E18: =PRODUCT(B18,D18) -> 40
A19: Frustacion | B19: 1 | C19: =D19/5 -> 5 | D19: 25 | E19: =PRODUCT(B19,D19) -> 25
A20: Total | B20: =SUM(B14,B15,B16,B17,B18,B19) -> 15 | E20: =SUM(E14:E19) -> 705 | F20: Porcentaje: | G20: =E20/B20 -> 47
A22: Edwin
A24: Variable | B24: (a) Peso | C24: (b) Puntuacion | D24: (c) Puntuacion Convertida (b*5) | E24: (d) Puntuacion Ponderada (c*a)
A25: Exigencia mental | B25: 3 | C25: 5 | D25: =PRODUCT(C25,5) -> 25 | E25: =PRODUCT(B25,D25) -> 75
A26: Exigencia fisica | B26: 1 | C26: 4 | D26: =PRODUCT(C26,5) -> 20 | E26: =PRODUCT(B26,D26) -> 20
A27: Exigencia Temporal | B27: 4 | C27: 5 | D27: =PRODUCT(C27,5) -> 25 | E27: =PRODUCT(B27,D27) -> 100
A28: Rendimiento | B28: 5 | C28: 11 | D28: =PRODUCT(C28,5) -> 55 | E28: =PRODUCT(B28,D28) -> 275
A29: Esfuerzo | B29: 2 | C29: 5 | D29: =PRODUCT(C29,5) -> 25 | E29: =PRODUCT(B29,D29) -> 50
A30: Frustacion | B30: 0 | C30: =D30/5 -> 4 | D30: 20 | E30: =PRODUCT(B30,D30) -> 0
A31: Total | B31: =SUM(B25,B26,B27,B28,B29,B30) -> 15 | E31: =SUM(E25:E30) -> 520 | F31: Porcentaje: | G31: =E31/B31 -> 34.666667
A33: Jeronimo
A35: Variable | B35: (a) Peso | C35: (b) Puntuacion | D35: (c) Puntuacion Convertida (b*5) | E35: (d) Puntuacion Ponderada (c*a)
A36: Exigencia mental | B36: 4 | C36: 2 | D36: =PRODUCT(C36,5) -> 10 | E36: =PRODUCT(B36,D36) -> 40
A37: Exigencia fisica | B37: 2 | C37: 2 | D37: =PRODUCT(C37,5) -> 10 | E37: =PRODUCT(B37,D37) -> 20
A38: Exigencia Temporal | B38: 5 | C38: 2 | D38: =PRODUCT(C38,5) -> 10 | E38: =PRODUCT(B38,D38) -> 50
A39: Rendimiento | B39: 1 | C39: 2 | D39: =PRODUCT(C39,5) -> 10 | E39: =PRODUCT(B39,D39) -> 10
A40: Esfuerzo | B40: 3 | C40: 2 | D40: =PRODUCT(C40,5) -> 10 | E40: =PRODUCT(B40,D40) -> 30
A41: Frustacion | B41: 0 | C41: =D41/5 -> 2 | D41: 10 | E41: =PRODUCT(B41,D41) -> 0
A42: Total | B42: =SUM(B36,B37,B38,B39,B40,B41) -> 15 | E42: =SUM(E36:E41) -> 150 | F42: Porcentaje: | G42: =E42/B42 -> 10
A44: Rafa
A46: Variable | B46: (a) Peso | C46: (b) Puntuacion | D46: (c) Puntuacion Convertida (b*5) | E46: (d) Puntuacion Ponderada (c*a)
A47: Exigencia mental | B47: 3 | C47: 4 | D47: =PRODUCT(C47,5) -> 20 | E47: =PRODUCT(B47,D47) -> 60
A48: Exigencia fisica | B48: 3 | C48: 6 | D48: =PRODUCT(C48,5) -> 30 | E48: =PRODUCT(B48,D48) -> 90
...

Sheet CanQuest (Teclado)
A1: Joselin
A2: Variable | B2: (a) Peso | C2: (b) Puntuacion | D2: (c) Puntuacion Convertida (b*5) | E2: (d) Puntuacion Ponderada (c*a)
A3: Exigencia mental | B3: 3 | C3: 12 | D3: =PRODUCT(C3,5) -> 60 | E3: =PRODUCT(B3,D3) -> 180
A4: Exigencia fisica | B4: 0 | C4: 8 | D4: =PRODUCT(C4,5) -> 40 | E4: =PRODUCT(B4,D4) -> 0
A5: Exigencia Temporal | B5: 1 | C5: 12 | D5: =PRODUCT(C5,5) -> 60 | E5: =PRODUCT(B5,D5) -> 60
A6: Rendimiento | B6: 4 | C6: 5 | D6: =PRODUCT(C6,5) -> 25 | E6: =PRODUCT(B6,D6) -> 100
A7: Esfuerzo | B7: 4 | C7: 12 | D7: =PRODUCT(C7,5) -> 60 | E7: =PRODUCT(B7,D7) -> 240
A8: Frustacion | B8: 3 | C8: =D8/5 -> 14 | D8: 70 | E8: =PRODUCT(B8,D8) -> 210
A9: Total | B9: =SUM(B3,B4,B5,B6,B7,B8) -> 15 | E9: =SUM(E3:E8) -> 790 | F9: Porcentaje: | G9: =E9/B9 -> 52.666667
A11: Daniel
A13: Variable | B13: (a) Peso | C13: (b) Puntuacion | D13: (c) Puntuacion Convertida (b*5) | E13: (d) Puntuacion Ponderada (c*a)
A14: Exigencia mental | B14: 5 | C14: 13 | D14: =PRODUCT(C14,5) -> 65 | E14: =PRODUCT(B14,D14) -> 325
A15: Exigencia fisica | B15: 0 | C15: 3 | D15: =PRODUCT(C15,5) -> 15 | E15: =PRODUCT(B15,D15) -> 0
A16: Exigencia Temporal | B16: 4 | C16: 4 | D16: =PRODUCT(C16,5) -> 20 | E16: =PRODUCT(B16,D16) -> 80
A17: Rendimiento | B17: 3 | C17: 15 | D17: =PRODUCT(C17,5) -> 75 | E17: =PRODUCT(B17,D17) -> 225
A18: Esfuerzo | B18: 2 | C18: 2 | D18: =PRODUCT(C18,5) -> 10 | E18: =PRODUCT(B18,D18) -> 20
A19: Frustacion | B19: 1 | C19: =D19/5 -> 3 | D19: 15 | E19: =PRODUCT(B19,D19) -> 15
A20: Total | B20: =SUM(B14,B15,B16,B17,B18,B19) -> 15 | E20: =SUM(E14:E19) -> 665 | F20: Porcentaje: | G20: =E20/B20 -> 44.333333
A22: Edwin
A24: Variable | B24: (a) Peso | C24: (b) Puntuacion | D24: (c) Puntuacion Convertida (b*5) | E24: (d) Puntuacion Ponderada (c*a)
A25: Exigencia mental | B25: 2 | C25: 4 | D25: =PRODUCT(C25,5) -> 20 | E25: =PRODUCT(B25,D25) -> 40
A26: Exigencia fisica | B26: 1 | C26: 3 | D26: =PRODUCT(C26,5) -> 15 | E26: =PRODUCT(B26,D26) -> 15
A27: Exigencia Temporal | B27: 4 | C27: 7 | D27: =PRODUCT(C27,5) -> 35 | E27: =PRODUCT(B27,D27) -> 140
A28: Rendimiento | B28: 3 | C28: 12 | D28: =PRODUCT(C28,5) -> 60 | E28: =PRODUCT(B28,D28) -> 180
A29: Esfuerzo | B29: 0 | C29: 4 | D29: =PRODUCT(C29,5) -> 20 | E29: =PRODUCT(B29,D29) -> 0
A30: Frustacion | B30: 5 | C30: =D30/5 -> 9 | D30: 45 | E30: =PRODUCT(B30,D30) -> 225
A31: Total | B31: =SUM(B25,B26,B27,B28,B29,B30) -> 15 | E31: =SUM(E25:E30) -> 600 | F31: Porcentaje: | G31: =E31/B31 -> 40
A33: Jeronimo
A35: Variable | B35: (a) Peso | C35: (b) Puntuacion | D35: (c) Puntuacion Convertida (b*5) | E35: (d) Puntuacion Ponderada (c*a)
A36: Exigencia mental | B36: 1 | C36: 5 | D36: =PRODUCT(C36,5) -> 25 | E36: =PRODUCT(B36,D36) -> 25
A37: Exigencia fisica | B37: 3 | C37: 5 | D37: =PRODUCT(C37,5) -> 25 | E37: =PRODUCT(B37,D37) -> 75
A38: Exigencia Temporal | B38: 0 | C38: 5 | D38: =PRODUCT(C38,5) -> 25 | E38: =PRODUCT(B38,D38) -> 0
A39: Rendimiento | B39: 2 | C39: 5 | D39: =PRODUCT(C39,5) -> 25 | E39: =PRODUCT(B39,D39) -> 50
A40: Esfuerzo | B40: 4 | C40: 5 | D40: =PRODUCT(C40,5) -> 25 | E40: =PRODUCT(B40,D40) -> 100
A41: Frustacion | B41: 5 | C41: =D41/5 -> 5 | D41: 25 | E41: =PRODUCT(B41,D41) -> 125
A42: Total | B42: =SUM(B36,B37,B38,B39,B40,B41) -> 15 | E42: =SUM(E36:E41) -> 375 | F42: Porcentaje: | G42: =E42/B42 -> 25
A44: Rafa
A46: Variable | B46: (a) Peso | C46: (b) Puntuacion | D46: (c) Puntuacion Convertida (b*5) | E46: (d) Puntuacion Ponderada (c*a)
A47: Exigencia mental | B47: 3 | C47: 4 | D47: =PRODUCT(C47,5) -> 20 | E47: =PRODUCT(B47,D47) -> 60
A48: Exigencia fisica | B48: 3 | C48: 6 | D48: =PRODUCT(C48,5) -> 30 | E48: =PRODUCT(B48,D48) -> 90
...

Sheet Laberinto
A1: Joselin
A2: Variable | B2: (a) Peso | C2: (b) Puntuacion | D2: (c) Puntuacion Convertida (b*5) | E2: (d) Puntuacion Ponderada (c*a)
A3: Exigencia mental | B3: 3 | C3: 12 | D3: =PRODUCT(C3,5) -> 60 | E3: =PRODUCT(B3,D3) -> 180
A4: Exigencia fisica | B4: 1 | C4: 5 | D4: =PRODUCT(C4,5) -> 25 | E4: =PRODUCT(B4,D4) -> 25
A5: Exigencia Temporal | B5: 2 | C5: 10 | D5: =PRODUCT(C5,5) -> 50 | E5: =PRODUCT(B5,D5) -> 100
A6: Rendimiento | B6: 2 | C6: 10 | D6: =PRODUCT(C6,5) -> 50 | E6: =PRODUCT(B6,D6) -> 100
A7: Esfuerzo | B7: 4 | C7: 5 | D7: =PRODUCT(C7,5) -> 25 | E7: =PRODUCT(B7,D7) -> 100
A8: Frustacion | B8: 3 | C8: =D8/5 -> 10 | D8: 50 | E8: =PRODUCT(B8,D8) -> 150
A9: Total | B9: =SUM(B3,B4,B5,B6,B7,B8) -> 15 | E9: =SUM(E3:E8) -> 655 | F9: Porcentaje: | G9: =E9/B9 -> 43.666667
A11: Daniel
A13: Variable | B13: (a) Peso | C13: (b) Puntuacion | D13: (c) Puntuacion Convertida (b*5) | E13: (d) Puntuacion Ponderada (c*a)
A14: Exigencia mental | B14: 4 | C14: 15 | D14: =PRODUCT(C14,5) -> 75 | E14: =PRODUCT(B14,D14) -> 300
A15: Exigencia fisica | B15: 2 | C15: 6 | D15: =PRODUCT(C15,5) -> 30 | E15: =PRODUCT(B15,D15) -> 60
A16: Exigencia Temporal | B16: 0 | C16: 10 | D16: =PRODUCT(C16,5) -> 50 | E16: =PRODUCT(B16,D16) -> 0
A17: Rendimiento | B17: 1 | C17: 10 | D17: =PRODUCT(C17,5) -> 50 | E17: =PRODUCT(B17,D17) -> 50
A18: Esfuerzo | B18: 5 | C18: 10 | D18: =PRODUCT(C18,5) -> 50 | E18: =PRODUCT(B18,D18) -> 250
A19: Frustacion | B19: 3 | C19: =D19/5 -> 15 | D19: 75 | E19: =PRODUCT(B19,D19) -> 225
A20: Total | B20: =SUM(B14,B15,B16,B17,B18,B19) -> 15 | E20: =SUM(E14:E19) -> 885 | F20: Porcentaje: | G20: =E20/B20 -> 59
A22: Edwin
A24: Variable | B24: (a) Peso | C24: (b) Puntuacion | D24: (c) Puntuacion Convertida (b*5) | E24: (d) Puntuacion Ponderada (c*a)
A25: Exigencia mental | B25: 2 | C25: 6 | D25: =PRODUCT(C25,5) -> 30 | E25: =PRODUCT(B25,D25) -> 60
A26: Exigencia fisica | B26: 2 | C26: 7 | D26: =PRODUCT(C26,5) -> 35 | E26: =PRODUCT(B26,D26) -> 70
A27: Exigencia Temporal | B27: 4 | C27: 16 | D27: =PRODUCT(C27,5) -> 80 | E27: =PRODUCT(B27,D27) -> 320
A28: Rendimiento | B28: 5 | C28: 16 | D28: =PRODUCT(C28,5) -> 80 | E28: =PRODUCT(B28,D28) -> 400
A29: Esfuerzo | B29: 2 | C29: 8 | D29: =PRODUCT(C29,5) -> 40 | E29: =PRODUCT(B29,D29) -> 80
A30: Frustacion | B30: 0 | C30: =D30/5 -> 5 | D30: 25 | E30: =PRODUCT(B30,D30) -> 0
A31: Total | B31: =SUM(B25,B26,B27,B28,B29,B30) -> 15 | E31: =SUM(E25:E30) -> 930 | F31: Porcentaje: | G31: =E31/B31 -> 62
A33: Jeronimo
A35: Variable | B35: (a) Peso | C35: (b) Puntuacion | D35: (c) Puntuacion Convertida (b*5) | E35: (d) Puntuacion Ponderada (c*a)
A36: Exigencia mental | B36: 4 | C36: 15 | D36: =PRODUCT(C36,5) -> 75 | E36: =PRODUCT(B36,D36) -> 300
A37: Exigencia fisica | B37: 2 | C37: 5 | D37: =PRODUCT(C37,5) -> 25 | E37: =PRODUCT(B37,D37) -> 50
A38: Exigencia Temporal | B38: 2 | C38: 10 | D38: =PRODUCT(C38,5) -> 50 | E38: =PRODUCT(B38,D38) -> 100
A39: Rendimiento | B39: 0 | C39: 10 | D39: =PRODUCT(C39,5) -> 50 | E39: =PRODUCT(B39,D39) -> 0
A40: Esfuerzo | B40: 3 | C40: 20 | D40: =PRODUCT(C40,5) -> 100 | E40: =PRODUCT(B40,D40) -> 300
A41: Frustacion | B41: 4 | C41: =D41/5 -> 5 | D41: 25 | E41: =PRODUCT(B41,D41) -> 100
A42: Total | B42: =SUM(B36,B37,B38,B39,B40,B41) -> 15 | E42: =SUM(E36:E41) -> 850 | F42: Porcentaje: | G42: =E42/B42 -> 56.666667
A44: Rafa
A46: Variable | B46: (a) Peso | C46: (b) Puntuacion | D46: (c) Puntuacion Convertida (b*5) | E46: (d) Puntuacion Ponderada (c*a)
A47: Exigencia mental | B47: 1 | C47: 12 | D47: =PRODUCT(C47,5) -> 60 | E47: =PRODUCT(B47,D47) -> 60
A48: Exigencia fisica | B48: 4 | C48: 14 | D48: =PRODUCT(C48,5) -> 70 | E48: =PRODUCT(B48,D48) -> 280
...

Sheet Resultados
A1: Persona | B1: % Carga cognitiva | C1: % CaniQuest Haptico | D1: %CaniQuest Gamepad | E1: %CaniQuest Teclado | F1: %Laberinto
A2: Joselin | B2: ='Carga cognitiva'!G9 -> 47.666667 | C2: ='CanQuest (Hápticos)'!G8 -> 52.333333 | D2: ='CanQuest (Control)'!G9 -> 38 | E2: ='CanQuest (Teclado)'!G9 -> 52.666667 | F2: =Laberinto!G9 -> 43.666667
A3: Daniel | B3: ='Carga cognitiva'!G20 -> 64 | C3: ='CanQuest (Hápticos)'!G18 -> 45 | D3: ='CanQuest (Control)'!G20 -> 47 | E3: ='CanQuest (Teclado)'!G20 -> 44.333333 | F3: =Laberinto!G20 -> 59
A4: Edwin | B4: ='Carga cognitiva'!G31 -> 57 | C4: ='CanQuest (Hápticos)'!G28 -> 54.333333 | D4: ='CanQuest (Control)'!G31 -> 34.666667 | E4: ='CanQuest (Teclado)'!G31 -> 40 | F4: =Laberinto!G31 -> 62
A5: Jeronimo | B5: ='Carga cognitiva'!G42 -> 46.333333 | C5: ='CanQuest (Hápticos)'!G39 -> 46.333333 | D5: ='CanQuest (Control)'!G42 -> 10 | E5: ='CanQuest (Teclado)'!G42 -> 25 | F5: =Laberinto!G42 -> 56.666667
A6: Rafa | B6: ='Carga cognitiva'!G53 -> 48.333333 | C6: ='CanQuest (Hápticos)'!G50 -> 48.333333 | D6: ='CanQuest (Control)'!G53 -> 44.333333 | E6: ='CanQuest (Teclado)'!G53 -> 22.333333 | F6: =Laberinto!G53 -> 55
A7: Eliza | B7: ='Carga cognitiva'!G64 -> 54 | C7: ='CanQuest (Hápticos)'!G61 -> 61 | D7: ='CanQuest (Control)'!G64 -> 38 | E7: ='CanQuest (Teclado)'!G64 -> 55 | F7: =Laberinto!G64 -> 61.666667
A8: Participante #7 | B8: ='Carga cognitiva'!G75 -> 53 | C8: ='CanQuest (Hápticos)'!G72 -> 34.333333 | D8: ='CanQuest (Control)'!G75 -> 28.666667 | E8: ='CanQuest (Teclado)'!G75 -> 42 | F8: 0
A9: Participante #8 | B9: ='Carga cognitiva'!G86 -> 13.333333 | C9: ='CanQuest (Hápticos)'!G83 -> 18 | D9: ='CanQuest (Control)'!G86 -> 60.333333 | E9: ='CanQuest (Teclado)'!G86 -> 75.666667 | F9: 0
A10: Participante #9 | B10: ='Carga cognitiva'!G97 -> 53.666667 | C10: ='CanQuest (Hápticos)'!G94 -> 37 | D10: ='CanQuest (Control)'!G97 -> 24.333333 | E10: ='CanQuest (Teclado)'!G97 -> 43.666667 | F10: 0
A11: Participante #10 | B11: ='Carga cognitiva'!G108 -> 50.333333 | C11: ='CanQuest (Hápticos)'!G105 -> 21.333333 | D11: ='CanQuest (Control)'!G108 -> 28.333333 | E11: ='CanQuest (Teclado)'!G108 -> 40 | F11: 0
